Workbook

Sheet All Applications
A1: Company | B1: Role | C1: Status | D1: Source | E1: Date Found | F1: Date Applied | G1: Email Confirmation | H1: Local Folder
A2: Alvin College | B2: Faculty, Computer Technology (12 Month) | C2: blocked_removed | D2: Local system (job-search automation) | E2: 2026-09-03
A3: Christopher Newport University | B3: Information Security Analyst | C3: interview | D3: Local system (job-search automation) | E3: 2026-09-03 | H3: 2026-09-03_Christopher-Newport-University_Information-Security-Analyst\status.json
A4: Horry-Georgetown Technical College | B4: Information Security Officer | C4: applied | D4: Local system (job-search automation) | E4: 2026-09-03 | F4: 2026-09-05 | H4: 2026-09-03_Horry-Georgetown-Technical-College_Information-Security-Officer\status.json
A5: Rutgers, The State University of New Jersey | B5: Senior Incident Response Analyst | C5: not_pursuing | D5: Local system (job-search automation) | E5: 2026-09-03 | H5: 2026-09-03_Rutgers-University_Senior-Incident-Response-Analyst\status.json
A6: Dolby | B6: IT Audit Manager | C6: applied | D6: Email only (self-submitted, not tracked locally) | E6: 2026-09-03 | F6: 2026-09-03 | G6: Received
A7: Sallie Mae | B7: Senior Associate, Technology Audit | C7: applied | D7: Local system + email confirmed | E7: 2026-08-31 | F7: 2026-09-02 | G7: Received | H7: 2026-08-31_Sallie-Mae_Senior-Associate-Technology-Audit\status.json
A8: BNSF Railway | B8: Cybersecurity Engineer I/II (Vulnerability & Patch Management) (Remote - US) | C8: applied_unverified | D8: Local system + email confirmed | E8: 2026-09-01 | F8: 2026-09-02 | G8: Received | H8: 2026-09-01_BNSF-Railway_Cybersecurity-Engineer-Vulnerability-Patch-Management\status.json
A9: CIG Companies Services | B9: Manager, Cybersecurity | C9: applied | D9: Email only (self-submitted, not tracked locally) | E9: 2026-09-02 | F9: 2026-09-02 | G9: Received
A10: Allina Health | B10: Manager Information Security | C10: needs_manual_completion | D10: Local system (job-search automation) | E10: 2026-09-01 | H10: 2026-09-01_Allina-Health_Manager-Information-Security\status.json
A11: Carey International Group, LLC | B11: Manager, Cybersecurity | C11: not_pursuing | D11: Local system (job-search automation) | E11: 2026-09-01 | H11: 2026-09-01_Carey-International-Group_Manager-Cybersecurity\status.json
A12: City Colleges of Chicago — Olive-Harvey College | B12: Full-Time Tenure Track Faculty — Computer Information Systems (Cybersecurity) | C12: staged | D12: Local system + email confirmed | E12: 2026-09-01 | G12: Received | H12: 2026-09-01_City-Colleges-of-Chicago_Full-Time-Faculty-CIS-Cybersecurity\status.json
A13: Hewlett Packard Enterprise (HPE) | B13: Cybersecurity Operations & Enablement | C13: closed | D13: Local system (job-search automation) | E13: 2026-09-01 | H13: 2026-09-01_HPE_Cybersecurity-Operations-Enablement\status.json
A14: Hewlett Packard Enterprise (HPE) | B14: Senior Cybersecurity Transformation Lead (Enterprise Programs) | C14: not_pursuing | D14: Local system (job-search automation) | E14: 2026-09-01 | H14: 2026-09-01_HPE_Senior-Cybersecurity-Transformation-Lead-Enterprise-Programs\status.json
A15: Hewlett Packard Enterprise (HPE) | B15: Senior Manager, Enterprise OS & Virtualization | C15: not_pursuing | D15: Local system (job-search automation) | E15: 2026-09-01 | H15: 2026-09-01_HPE_Senior-Manager-Enterprise-OS-Virtualization\status.json
A16: KLA | B16: Digital Forensics & eDiscovery Manager | C16: applied | D16: Local system (job-search automation) | E16: 2026-09-01 | H16: 2026-09-01_KLA_Digital-Forensics-eDiscovery-Manager\status.json
A17: KLA | B17: IT Cybersecurity Operations Manager | C17: applied | D17: Local system (job-search automation) | E17: 2026-09-01 | H17: 2026-09-01_KLA_IT-Cybersecurity-Operations-Manager\status.json
A18: Lumiture | B18: Cyber Security Analyst | C18: applied | D18: Local system (job-search automation) | E18: 2026-09-01 | F18: 2026-09-03 | H18: 2026-09-01_Lumiture_Cyber-Security-Analyst\status.json
A19: Nebius | B19: Technical Account Manager - Token Factory | C19: rejected | D19: Local system (job-search automation) | E19: 2026-09-01 | F19: 2026-09-04 | H19: 2026-09-01_Nebius_Technical-Account-Manager-Token-Factory\status.json
A20: New Resources Consulting (client direct-hire) | B20: IT Cybersecurity Engineer | C20: applied | D20: Local system (job-search automation) | E20: 2026-09-01 | F20: 2026-09-05 | H20: 2026-09-01_New-Resources-Consulting_IT-Cybersecurity-Engineer\status.json
A21: SGMC Health | B21: Network Security Analyst, Information Services | C21: closed | D21: Local system (job-search automation) | E21: 2026-09-01 | H21: 2026-09-01_SGMC-Health_Network-Security-Analyst\status.json
A22: Travelers | B22: Cybersecurity Ops Technologist - Splunk SIEM Engineer (R-51597) | C22: staged | D22: Local system (job-search automation) | E22: 2026-09-01 | H22: 2026-09-01_Travelers_Cybersecurity-Ops-Technologist-Splunk-SIEM-Engineer\status.json
A23: Optum / UnitedHealth Group | B23: AI Security Governance Operations Specialist (listed as 'Information Security Governance Operations Support Analyst') | C23: closed | D23: Local system (job-search automation) | E23: 2026-09-01 | H23: 2026-09-01_UnitedHealth-Optum_AI-Security-Governance-Operations-Specialist\status.json
A24: University of Louisville | B24: IT Systems Engineer V (Cybersecurity Engineer) — R109233 | C24: Applied (auto-submission via Simplify) | D24: Local system (job-search automation) | E24: 2026-09-01 | F24: 2026-09-04 | G24: Discovered via Workday page banner: already applied 9/4/2026 via Simplify | H24: applications/2026-09-06_University-of-Louisville_IT-Systems-Engineer-V-Cybersecurity-Engineer-discovered
A25: University of New Hampshire | B25: Cybersecurity Operations Engineer | C25: applied | D25: Local system (job-search automation) | E25: 2026-09-01 | F25: 2026-09-04 | H25: 2026-09-01_University-of-New-Hampshire_Cybersecurity-Operations-Engineer\status.json
A26: University of Wisconsin - Madison | B26: Cybersecurity Analyst — College of Agricultural and Life Sciences (CALS) | C26: applied | D26: Local system + email confirmed | E26: 2026-09-01 | F26: 2026-09-05 | G26: Received | H26: 2026-09-01_University-of-Wisconsin-Madison_Cybersecurity-Analyst\status.json
A27: University of Wisconsin - Madison | B27: Information Systems and Web Application Security Analyst — School of Pharmacy | C27: applied | D27: Local system (job-search automation) | E27: 2026-09-01 | F27: 2026-09-03 | H27: 2026-09-01_University-of-Wisconsin-Madison_Information-Systems-and-Web-Application-Security-Analyst\status.json
A28: Verisign | B28: Manager - Information Security Compliance | C28: applied | D28: Local system (job-search automation) | E28: 2026-09-01 | F28: 2026-09-05 | H28: 2026-09-01_Verisign_Manager-Information-Security-Compliance\status.json
A29: Veritis Group Inc | B29: Technology & Cybersecurity Risk Management Analyst | C29: closed | D29: Local system (job-search automation) | E29: 2026-09-01 | H29: 2026-09-01_Veritis-Group_Technology-Cybersecurity-Risk-Management-Analyst\status.json
A30: Georgia Gwinnett College | B30: Security Operations Center (SOC) Lead | C30: needs_manual_completion | D30: Local system (job-search automation) | E30: 2026-08-31 | H30: 2026-08-31_Georgia-Gwinnett-College_Security-Operations-Center-SOC-Lead\status.json
A31: Southern New Hampshire University | B31: IAM Engineer | C31: not_pursuing | D31: Local system (job-search automation) | E31: 2026-08-31 | H31: 2026-08-31_Southern-New-Hampshire-University_IAM-Engineer\status.json
A32: Princeton University | B32: IT Risk & Information Security Analyst (University Services) | C32: applied | D32: Local system (job-search automation) | E32: 2026-08-22 | F32: 2026-08-30 | H32: 2026-08-22_Princeton-University_IT-Risk-and-Information-Security-Analyst\status.json
A33: Albany Medical Center | B33: IT Security Manager | C33: applied | D33: Local system + email confirmed | E33: 2026-08-29 | F33: 2026-08-30 | G33: Rejected | H33: 2026-08-29_Albany-Medical-Center_IT-Security-Manager\status.json
A34: IBM | B34: Advisory Data Scientist, IBM Quantum | C34: rejected | D34: Local system + email confirmed | E34: 2026-08-29 | F34: 2026-08-30 | G34: Received | H34: 2026-08-29_IBM_Advisory-Data-Scientist-IBM-Quantum\status.json
A35: The MITRE Corporation | B35: Internships in Cybersecurity and Information Security (general talent pool, not a specific role) | C35: applied | D35: Local system (job-search automation) | E35: 2026-08-29 | F35: 2026-08-30 | H35: 2026-08-29_MITRE-Corporation_Cybersecurity-Internship\status.json
A36: Nebius | B36: DC Operations Manager - Critical Infrastructure | C36: applied | D36: Local system + email confirmed | E36: 2026-08-30 | F36: 2026-08-30 | G36: Received | H36: 2026-08-30_Nebius_DC-Operations-Manager-Critical-Infrastructure\status.json
A37: Nebius | B37: IT Risks & Control Manager | C37: applied | D37: Local system (job-search automation) | E37: 2026-08-30 | F37: 2026-08-30 | H37: 2026-08-30_Nebius_IT-Risks-Control-Manager\status.json
A38: Team Cymru | B38: Technical Trainer - Curriculum Developer | C38: applied | D38: Local system (job-search automation) | E38: 2026-08-30 | F38: 2026-08-30 | H38: 2026-08-30_Team-Cymru_Technical-Trainer-Curriculum-Developer\status.json
A39: Wake Technical Community College | B39: Instructor 9M Cybersecurity, Digital Forensics | C39: not_pursuing | D39: Local system (job-search automation) | E39: 2026-08-30 | H39: 2026-08-30_Wake-Technical-Community-College_Instructor-Cybersecurity-Digital-Forensics\status.json
A40: Aquent | Skill | B40: Fraud Analytics & Strategy Manager | C40: applied | D40: Email only (self-submitted, not tracked locally) | E40: 2026-08-30 | F40: 2026-08-30 | G40: Received
...

Sheet Summary
B2: Job Search Tracker — Summary
B3: Combines applications tracked by the automated job-search system with confirmation emails found in Gmail (inbox + trash)
B5: Total Unique Applications Tracked | C5: =COUNTA('All Applications'!A2:A140)
B7: By Status
B8: applied | C8: =COUNTIF('All Applications'!C2:C140,"applied")
B9: interview | C9: =COUNTIF('All Applications'!C2:C140,"interview")
B10: applied_unverified | C10: =COUNTIF('All Applications'!C2:C140,"applied_unverified")
B11: staged | C11: =COUNTIF('All Applications'!C2:C140,"staged")
B12: needs_manual_completion | C12: =COUNTIF('All Applications'!C2:C140,"needs_manual_completion")
B13: rejected | C13: =COUNTIF('All Applications'!C2:C140,"rejected")
B14: not_pursuing | C14: =COUNTIF('All Applications'!C2:C140,"not_pursuing")
B15: closed | C15: =COUNTIF('All Applications'!C2:C140,"closed")
B17: By Source
B18: Local system + email confirmed | C18: =COUNTIF('All Applications'!D2:D140,"Local system + email confirmed")
B19: Local system (job-search automation) | C19: =COUNTIF('All Applications'!D2:D140,"Local system (job-search automation)")
B20: Email only (self-submitted, not tracked locally) | C20: =COUNTIF('All Applications'!D2:D140,"Email only (self-submitted, not tracked locally)")
B22: By Month (Date Applied/Found)
B23: Note: a row counts in two months if its Found and Applied dates differ.
B24: 2025-12 | C24: =SUMPRODUCT((LEFT('All Applications'!E2:E140,7)="2025-12")*1)+SUMPRODUCT((LEFT('All Applications'!E2:E140,7)<>"2025-12")*(LEFT('All Applications'!F2:F140,7)="2025-12")*1)
B25: 2026-01 | C25: =SUMPRODUCT((LEFT('All Applications'!E2:E140,7)="2026-01")*1)+SUMPRODUCT((LEFT('All Applications'!E2:E140,7)<>"2026-01")*(LEFT('All Applications'!F2:F140,7)="2026-01")*1)
B26: 2026-02 | C26: =SUMPRODUCT((LEFT('All Applications'!E2:E140,7)="2026-02")*1)+SUMPRODUCT((LEFT('All Applications'!E2:E140,7)<>"2026-02")*(LEFT('All Applications'!F2:F140,7)="2026-02")*1)
B27: 2026-03 | C27: =SUMPRODUCT((LEFT('All Applications'!E2:E140,7)="2026-03")*1)+SUMPRODUCT((LEFT('All Applications'!E2:E140,7)<>"2026-03")*(LEFT('All Applications'!F2:F140,7)="2026-03")*1)
B28: 2026-04 | C28: =SUMPRODUCT((LEFT('All Applications'!E2:E140,7)="2026-04")*1)+SUMPRODUCT((LEFT('All Applications'!E2:E140,7)<>"2026-04")*(LEFT('All Applications'!F2:F140,7)="2026-04")*1)
B29: 2026-05 | C29: =SUMPRODUCT((LEFT('All Applications'!E2:E140,7)="2026-05")*1)+SUMPRODUCT((LEFT('All Applications'!E2:E140,7)<>"2026-05")*(LEFT('All Applications'!F2:F140,7)="2026-05")*1)
B30: 2026-06 | C30: =SUMPRODUCT((LEFT('All Applications'!E2:E140,7)="2026-06")*1)+SUMPRODUCT((LEFT('All Applications'!E2:E140,7)<>"2026-06")*(LEFT('All Applications'!F2:F140,7)="2026-06")*1)
B31: 2026-07 | C31: =SUMPRODUCT((LEFT('All Applications'!E2:E140,7)="2026-07")*1)+SUMPRODUCT((LEFT('All Applications'!E2:E140,7)<>"2026-07")*(LEFT('All Applications'!F2:F140,7)="2026-07")*1)
B32: 2026-08 | C32: =SUMPRODUCT((LEFT('All Applications'!E2:E140,7)="2026-08")*1)+SUMPRODUCT((LEFT('All Applications'!E2:E140,7)<>"2026-08")*(LEFT('All Applications'!F2:F140,7)="2026-08")*1)
B33: 2026-09 | C33: =SUMPRODUCT((LEFT('All Applications'!E2:E140,7)="2026-09")*1)+SUMPRODUCT((LEFT('All Applications'!E2:E140,7)<>"2026-09")*(LEFT('All Applications'!F2:F140,7)="2026-09")*1)

Sheet Email-Only Applications
A1: Date | B1: Company | C1: Role | D1: Email Status | E1: Gmail Folder
A2: 2026-09-03 | B2: Dolby | C2: IT Audit Manager | D2: Received | E2: INBOX
A3: 2026-09-02 | B3: CIG Companies Services | C3: Manager, Cybersecurity | D3: Received | E3: TRASH
A4: 2026-08-30 | B4: Aquent | Skill | C4: Fraud Analytics & Strategy Manager | D4: Received | E4: TRASH
A5: 2026-08-30 | B5: Aquent | Skill | C5: IT - Cyber Security Developer | D5: Received | E5: TRASH
A6: 2026-08-30 | B6: Spectrum Comm Inc | C6: Systems Analyst | D6: Rejected | E6: TRASH
A7: 2026-08-30 | B7: MetroStar | C7: (role not specified in confirmation) | D7: Received | E7: TRASH
A8: 2026-08-30 | B8: Iron Bow Technologies | C8: PKI, Cryptography and Zero Trust Architect | D8: Received | E8: TRASH
A9: 2026-08-30 | B9: Iron Bow Technologies | C9: Post-Quantum Cryptography Specialist | D9: Received | E9: TRASH
A10: 2026-08-30 | B10: Authentic Brands Group | C10: Manager, IT Security and Compliance | D10: Received | E10: TRASH
A11: 2026-08-25 | B11: CardWorks | C11: Director, Security Risk Management | D11: Rejected | E11: TRASH
A12: 2026-08-24 | B12: Antier Solutions Pvt. Ltd | C12: Cybersecurity Trainer | D12: Received | E12: TRASH
... A39: 2026-08-08 | B39: Horry County, SC | C39: (role not specified in confirmation) | D39: Received | E39: TRASH
